[0m14:22:12.275938 [debug] [MainThread]: Sending event: {'category': 'dbt', 'action': 'invocation', 'label': 'start', 'context': [<snowplow_tracker.self_describing_json.SelfDescribingJson object at 0x106117b60>, <snowplow_tracker.self_describing_json.SelfDescribingJson object at 0x1079339d0>, <snowplow_tracker.self_describing_json.SelfDescribingJson object at 0x107933b10>]}


============================== 14:22:12.278732 | ec929687-a843-45ea-a560-e22a265dd032 ==============================
[0m14:22:12.278732 [info ] [MainThread]: Running with dbt=1.10.9
[0m14:22:12.279021 [debug] [MainThread]: running dbt with arguments {'write_json': 'True', 'invocation_command': 'dbt init', 'warn_error': 'None', 'indirect_selection': 'eager', 'use_colors': 'True', 'log_format': 'default', 'partial_parse': 'True', 'profiles_dir': '/Users/diaw/.dbt', 'introspect': 'True', 'empty': 'None', 'warn_error_options': 'WarnErrorOptionsV2(error=[], warn=[], silence=[])', 'quiet': 'False', 'version_check': 'True', 'no_print': 'None', 'fail_fast': 'False', 'log_cache_events': 'False', 'static_parser': 'True', 'cache_selected_only': 'False', 'use_experimental_parser': 'False', 'log_path': 'logs', 'printer_width': '80', 'target_path': 'None', 'debug': 'False', 'send_anonymous_usage_stats': 'True'}
[0m14:22:12.290093 [info ] [MainThread]: Creating dbt configuration folder at /Users/diaw/.dbt
[0m14:23:45.932243 [debug] [MainThread]: Starter project path: /Users/diaw/Downloads/dbt_notlimitail/dbt-env_notlimitail/lib/python3.13/site-packages/dbt/include/starter_project
[0m14:23:45.943383 [info ] [MainThread]: 
Your new dbt project "dbt_notlimi_project" was created!

For more information on how to configure the profiles.yml file,
please consult the dbt documentation here:

  https://docs.getdbt.com/docs/configure-your-profile

One more thing:

Need help? Don't hesitate to reach out to us via GitHub issues or on Slack:

  https://community.getdbt.com/

Happy modeling!

[0m14:23:45.943810 [info ] [MainThread]: Setting up your profile.
[0m14:50:27.241802 [info ] [MainThread]: Profile dbt_notlimi_project written to /Users/diaw/.dbt/profiles.yml using target's profile_template.yml and your supplied values. Run 'dbt debug' to validate the connection.
[0m14:50:27.348202 [debug] [MainThread]: Resource report: {"command_name": "init", "command_success": true, "command_wall_clock_time": 1695.0988, "process_in_blocks": "0", "process_kernel_time": 0.524242, "process_mem_max_rss": "347914240", "process_out_blocks": "0", "process_user_time": 1.773754}
[0m14:50:27.354481 [debug] [MainThread]: Command `dbt init` succeeded at 14:50:27.354217 after 1695.11 seconds
[0m14:50:27.355486 [debug] [MainThread]: Sending event: {'category': 'dbt', 'action': 'invocation', 'label': 'end', 'context': [<snowplow_tracker.self_describing_json.SelfDescribingJson object at 0x12d291220>, <snowplow_tracker.self_describing_json.SelfDescribingJson object at 0x12d2ac830>, <snowplow_tracker.self_describing_json.SelfDescribingJson object at 0x12d1bf350>]}
[0m14:50:27.356086 [debug] [MainThread]: Flushing usage events
[0m14:50:27.758253 [debug] [MainThread]: An error was encountered while trying to flush usage events
[0m14:58:01.294060 [debug] [MainThread]: Sending event: {'category': 'dbt', 'action': 'invocation', 'label': 'start', 'context': [<snowplow_tracker.self_describing_json.SelfDescribingJson object at 0x105dc3b60>, <snowplow_tracker.self_describing_json.SelfDescribingJson object at 0x11083f9d0>, <snowplow_tracker.self_describing_json.SelfDescribingJson object at 0x11083fb10>]}


============================== 14:58:01.297368 | 563d10c3-9c4a-4918-82a9-950be64ed2c9 ==============================
[0m14:58:01.297368 [info ] [MainThread]: Running with dbt=1.10.9
[0m14:58:01.297669 [debug] [MainThread]: running dbt with arguments {'profiles_dir': '/Users/diaw/.dbt', 'cache_selected_only': 'False', 'log_format': 'default', 'target_path': 'None', 'partial_parse': 'True', 'write_json': 'True', 'warn_error_options': 'WarnErrorOptionsV2(error=[], warn=[], silence=[])', 'empty': 'False', 'introspect': 'True', 'invocation_command': 'dbt compile', 'no_print': 'None', 'log_path': 'logs', 'fail_fast': 'False', 'debug': 'False', 'send_anonymous_usage_stats': 'True', 'log_cache_events': 'False', 'version_check': 'True', 'quiet': 'False', 'indirect_selection': 'eager', 'use_colors': 'True', 'static_parser': 'True', 'warn_error': 'None', 'use_experimental_parser': 'False', 'printer_width': '80'}
[0m14:58:01.297963 [error] [MainThread]: Encountered an error:
Runtime Error
  No dbt_project.yml found at expected path /Users/diaw/Downloads/dbt_notlimitail/dbt_project.yml
  Verify that each entry within packages.yml (and their transitive dependencies) contains a file named dbt_project.yml
  
[0m14:58:01.299637 [debug] [MainThread]: Resource report: {"command_name": "compile", "command_success": false, "command_wall_clock_time": 0.045595083, "process_in_blocks": "0", "process_kernel_time": 0.113227, "process_mem_max_rss": "106217472", "process_out_blocks": "0", "process_user_time": 0.616372}
[0m14:58:01.299863 [debug] [MainThread]: Command `dbt compile` failed at 14:58:01.299820 after 0.05 seconds
[0m14:58:01.300023 [debug] [MainThread]: Sending event: {'category': 'dbt', 'action': 'invocation', 'label': 'end', 'context': [<snowplow_tracker.self_describing_json.SelfDescribingJson object at 0x110737360>, <snowplow_tracker.self_describing_json.SelfDescribingJson object at 0x11073eb10>, <snowplow_tracker.self_describing_json.SelfDescribingJson object at 0x1106d99d0>]}
[0m14:58:01.300172 [debug] [MainThread]: Flushing usage events
[0m14:58:01.667518 [debug] [MainThread]: An error was encountered while trying to flush usage events
[0m14:58:33.128970 [debug] [MainThread]: Sending event: {'category': 'dbt', 'action': 'invocation', 'label': 'start', 'context': [<snowplow_tracker.self_describing_json.SelfDescribingJson object at 0x111807b60>, <snowplow_tracker.self_describing_json.SelfDescribingJson object at 0x11343f9d0>, <snowplow_tracker.self_describing_json.SelfDescribingJson object at 0x11343fb10>]}


============================== 14:58:33.131798 | 1550070f-8990-42c4-a09a-a3d699253d40 ==============================
[0m14:58:33.131798 [info ] [MainThread]: Running with dbt=1.10.9
[0m14:58:33.132101 [debug] [MainThread]: running dbt with arguments {'fail_fast': 'False', 'introspect': 'True', 'partial_parse': 'True', 'write_json': 'True', 'log_format': 'default', 'profiles_dir': '/Users/diaw/.dbt', 'no_print': 'None', 'static_parser': 'True', 'warn_error': 'None', 'printer_width': '80', 'empty': 'False', 'version_check': 'True', 'invocation_command': 'dbt compile', 'use_colors': 'True', 'cache_selected_only': 'False', 'send_anonymous_usage_stats': 'True', 'log_path': 'logs', 'quiet': 'False', 'log_cache_events': 'False', 'indirect_selection': 'eager', 'warn_error_options': 'WarnErrorOptionsV2(error=[], warn=[], silence=[])', 'use_experimental_parser': 'False', 'target_path': 'None', 'debug': 'False'}
[0m14:58:33.132371 [error] [MainThread]: Encountered an error:
Runtime Error
  No dbt_project.yml found at expected path /Users/diaw/Downloads/dbt_notlimitail/dbt_project.yml
  Verify that each entry within packages.yml (and their transitive dependencies) contains a file named dbt_project.yml
  
[0m14:58:33.134053 [debug] [MainThread]: Resource report: {"command_name": "compile", "command_success": false, "command_wall_clock_time": 0.04065154, "process_in_blocks": "0", "process_kernel_time": 0.117369, "process_mem_max_rss": "106790912", "process_out_blocks": "0", "process_user_time": 0.615156}
[0m14:58:33.134303 [debug] [MainThread]: Command `dbt compile` failed at 14:58:33.134257 after 0.04 seconds
[0m14:58:33.134454 [debug] [MainThread]: Sending event: {'category': 'dbt', 'action': 'invocation', 'label': 'end', 'context': [<snowplow_tracker.self_describing_json.SelfDescribingJson object at 0x113337360>, <snowplow_tracker.self_describing_json.SelfDescribingJson object at 0x11333eb10>, <snowplow_tracker.self_describing_json.SelfDescribingJson object at 0x1132d99d0>]}
[0m14:58:33.134591 [debug] [MainThread]: Flushing usage events
[0m14:58:33.527466 [debug] [MainThread]: An error was encountered while trying to flush usage events
[0m15:04:52.702944 [debug] [MainThread]: Sending event: {'category': 'dbt', 'action': 'invocation', 'label': 'start', 'context': [<snowplow_tracker.self_describing_json.SelfDescribingJson object at 0x104007b60>, <snowplow_tracker.self_describing_json.SelfDescribingJson object at 0x105d3f9d0>, <snowplow_tracker.self_describing_json.SelfDescribingJson object at 0x105d3fb10>]}


============================== 15:04:52.705948 | e83d42f0-b9b4-4fa2-99bc-d7fafb486df5 ==============================
[0m15:04:52.705948 [info ] [MainThread]: Running with dbt=1.10.9
[0m15:04:52.706228 [debug] [MainThread]: running dbt with arguments {'version_check': 'True', 'empty': 'False', 'warn_error': 'None', 'introspect': 'True', 'partial_parse': 'True', 'quiet': 'False', 'printer_width': '80', 'write_json': 'True', 'target_path': 'None', 'no_print': 'None', 'cache_selected_only': 'False', 'fail_fast': 'False', 'log_format': 'default', 'indirect_selection': 'eager', 'invocation_command': 'dbt compile', 'log_cache_events': 'False', 'send_anonymous_usage_stats': 'True', 'use_colors': 'True', 'static_parser': 'True', 'profiles_dir': '/Users/diaw/.dbt', 'log_path': 'logs', 'warn_error_options': 'WarnErrorOptionsV2(error=[], warn=[], silence=[])', 'use_experimental_parser': 'False', 'debug': 'False'}
[0m15:04:52.706475 [error] [MainThread]: Encountered an error:
Runtime Error
  No dbt_project.yml found at expected path /Users/diaw/Downloads/dbt_notlimitail/dbt_project.yml
  Verify that each entry within packages.yml (and their transitive dependencies) contains a file named dbt_project.yml
  
[0m15:04:52.708076 [debug] [MainThread]: Resource report: {"command_name": "compile", "command_success": false, "command_wall_clock_time": 0.040123917, "process_in_blocks": "0", "process_kernel_time": 0.112237, "process_mem_max_rss": "107216896", "process_out_blocks": "0", "process_user_time": 0.613143}
[0m15:04:52.708308 [debug] [MainThread]: Command `dbt compile` failed at 15:04:52.708265 after 0.04 seconds
[0m15:04:52.708455 [debug] [MainThread]: Sending event: {'category': 'dbt', 'action': 'invocation', 'label': 'end', 'context': [<snowplow_tracker.self_describing_json.SelfDescribingJson object at 0x105c37360>, <snowplow_tracker.self_describing_json.SelfDescribingJson object at 0x105c3eb10>, <snowplow_tracker.self_describing_json.SelfDescribingJson object at 0x105ad99d0>]}
[0m15:04:52.708604 [debug] [MainThread]: Flushing usage events
[0m15:04:53.062961 [debug] [MainThread]: An error was encountered while trying to flush usage events
[0m11:46:29.456922 [debug] [MainThread]: Sending event: {'category': 'dbt', 'action': 'invocation', 'label': 'start', 'context': [<snowplow_tracker.self_describing_json.SelfDescribingJson object at 0x10322fb60>, <snowplow_tracker.self_describing_json.SelfDescribingJson object at 0x1058379d0>, <snowplow_tracker.self_describing_json.SelfDescribingJson object at 0x105837b10>]}


============================== 11:46:29.459772 | 869324ce-723a-41cb-abe3-6710421b366c ==============================
[0m11:46:29.459772 [info ] [MainThread]: Running with dbt=1.10.9
[0m11:46:29.460092 [debug] [MainThread]: running dbt with arguments {'target_path': 'None', 'log_format': 'default', 'send_anonymous_usage_stats': 'True', 'debug': 'False', 'profiles_dir': '/Users/diaw/.dbt', 'warn_error_options': 'WarnErrorOptionsV2(error=[], warn=[], silence=[])', 'no_print': 'None', 'log_path': 'logs', 'printer_width': '80', 'log_cache_events': 'False', 'use_colors': 'True', 'empty': 'None', 'introspect': 'True', 'write_json': 'True', 'indirect_selection': 'eager', 'use_experimental_parser': 'False', 'invocation_command': 'dbt run-operation generate_source --args {"schema_name": "thelook_ecommerce", "database_name": "bigquery-public-data", "table_names": ["users", "products", "orders", "order_items"]}', 'static_parser': 'True', 'version_check': 'True', 'warn_error': 'None', 'partial_parse': 'True', 'cache_selected_only': 'False', 'quiet': 'False', 'fail_fast': 'False'}
[0m11:46:29.460585 [error] [MainThread]: Encountered an error:
Runtime Error
  No dbt_project.yml found at expected path /Users/diaw/Downloads/dbt_notlimitail/dbt_project.yml
  Verify that each entry within packages.yml (and their transitive dependencies) contains a file named dbt_project.yml
  
[0m11:46:29.462056 [debug] [MainThread]: Resource report: {"command_name": "run-operation", "command_success": false, "command_wall_clock_time": 0.03956054, "process_in_blocks": "0", "process_kernel_time": 0.097133, "process_mem_max_rss": "106659840", "process_out_blocks": "0", "process_user_time": 0.616024}
[0m11:46:29.462281 [debug] [MainThread]: Command `dbt run-operation` failed at 11:46:29.462234 after 0.04 seconds
[0m11:46:29.462425 [debug] [MainThread]: Sending event: {'category': 'dbt', 'action': 'invocation', 'label': 'end', 'context': [<snowplow_tracker.self_describing_json.SelfDescribingJson object at 0x104f37360>, <snowplow_tracker.self_describing_json.SelfDescribingJson object at 0x104f3eb10>, <snowplow_tracker.self_describing_json.SelfDescribingJson object at 0x104ed99d0>]}
[0m11:46:29.462578 [debug] [MainThread]: Flushing usage events
[0m11:46:29.814842 [debug] [MainThread]: An error was encountered while trying to flush usage events
[0m12:15:24.333282 [debug] [MainThread]: Sending event: {'category': 'dbt', 'action': 'invocation', 'label': 'start', 'context': [<snowplow_tracker.self_describing_json.SelfDescribingJson object at 0x103a37b60>, <snowplow_tracker.self_describing_json.SelfDescribingJson object at 0x104f479d0>, <snowplow_tracker.self_describing_json.SelfDescribingJson object at 0x104f47b10>]}


============================== 12:15:24.336137 | b785fb3d-600d-42ac-aeab-53ca6df2b121 ==============================
[0m12:15:24.336137 [info ] [MainThread]: Running with dbt=1.10.9
[0m12:15:24.336431 [debug] [MainThread]: running dbt with arguments {'fail_fast': 'False', 'introspect': 'True', 'warn_error': 'None', 'no_print': 'None', 'log_path': 'logs', 'debug': 'False', 'profiles_dir': '/Users/diaw/.dbt', 'printer_width': '80', 'send_anonymous_usage_stats': 'True', 'version_check': 'True', 'log_cache_events': 'False', 'empty': 'None', 'static_parser': 'True', 'warn_error_options': 'WarnErrorOptionsV2(error=[], warn=[], silence=[])', 'invocation_command': 'dbt deps', 'target_path': 'None', 'indirect_selection': 'eager', 'use_experimental_parser': 'False', 'use_colors': 'True', 'cache_selected_only': 'False', 'log_format': 'default', 'quiet': 'False', 'write_json': 'True', 'partial_parse': 'True'}
[0m12:15:24.336840 [error] [MainThread]: Encountered an error:
Runtime Error
  No dbt_project.yml found at expected path /Users/diaw/Downloads/dbt_notlimitail/dbt_project.yml
  Verify that each entry within packages.yml (and their transitive dependencies) contains a file named dbt_project.yml
  
[0m12:15:24.338247 [debug] [MainThread]: Resource report: {"command_name": "deps", "command_success": false, "command_wall_clock_time": 0.045686416, "process_in_blocks": "0", "process_kernel_time": 0.113897, "process_mem_max_rss": "107233280", "process_out_blocks": "0", "process_user_time": 0.622815}
[0m12:15:24.338483 [debug] [MainThread]: Command `dbt deps` failed at 12:15:24.338439 after 0.05 seconds
[0m12:15:24.338636 [debug] [MainThread]: Sending event: {'category': 'dbt', 'action': 'invocation', 'label': 'end', 'context': [<snowplow_tracker.self_describing_json.SelfDescribingJson object at 0x104e4b360>, <snowplow_tracker.self_describing_json.SelfDescribingJson object at 0x104e52b10>, <snowplow_tracker.self_describing_json.SelfDescribingJson object at 0x104dedae0>]}
[0m12:15:24.338775 [debug] [MainThread]: Flushing usage events
[0m12:15:24.711352 [debug] [MainThread]: An error was encountered while trying to flush usage events
[0m12:22:22.367218 [debug] [MainThread]: Sending event: {'category': 'dbt', 'action': 'invocation', 'label': 'start', 'context': [<snowplow_tracker.self_describing_json.SelfDescribingJson object at 0x10596bb60>, <snowplow_tracker.self_describing_json.SelfDescribingJson object at 0x107d379d0>, <snowplow_tracker.self_describing_json.SelfDescribingJson object at 0x107d37b10>]}


============================== 12:22:22.370212 | 597fe174-bd88-4a9d-bbde-74562aedfe5d ==============================
[0m12:22:22.370212 [info ] [MainThread]: Running with dbt=1.10.9
[0m12:22:22.370508 [debug] [MainThread]: running dbt with arguments {'no_print': 'None', 'partial_parse': 'True', 'warn_error': 'None', 'fail_fast': 'False', 'static_parser': 'True', 'target_path': 'None', 'log_format': 'default', 'printer_width': '80', 'cache_selected_only': 'False', 'log_path': 'logs', 'quiet': 'False', 'send_anonymous_usage_stats': 'True', 'profiles_dir': '/Users/diaw/.dbt', 'use_colors': 'True', 'empty': 'None', 'invocation_command': 'dbt deps', 'write_json': 'True', 'indirect_selection': 'eager', 'warn_error_options': 'WarnErrorOptionsV2(error=[], warn=[], silence=[])', 'introspect': 'True', 'debug': 'False', 'use_experimental_parser': 'False', 'log_cache_events': 'False', 'version_check': 'True'}
[0m12:22:22.370907 [error] [MainThread]: Encountered an error:
Runtime Error
  No dbt_project.yml found at expected path /Users/diaw/Downloads/dbt_notlimitail/dbt_project.yml
  Verify that each entry within packages.yml (and their transitive dependencies) contains a file named dbt_project.yml
  
[0m12:22:22.372646 [debug] [MainThread]: Resource report: {"command_name": "deps", "command_success": false, "command_wall_clock_time": 0.040079664, "process_in_blocks": "0", "process_kernel_time": 0.105599, "process_mem_max_rss": "106774528", "process_out_blocks": "0", "process_user_time": 0.616471}
[0m12:22:22.372908 [debug] [MainThread]: Command `dbt deps` failed at 12:22:22.372861 after 0.04 seconds
[0m12:22:22.373071 [debug] [MainThread]: Sending event: {'category': 'dbt', 'action': 'invocation', 'label': 'end', 'context': [<snowplow_tracker.self_describing_json.SelfDescribingJson object at 0x107c37360>, <snowplow_tracker.self_describing_json.SelfDescribingJson object at 0x107c3eb10>, <snowplow_tracker.self_describing_json.SelfDescribingJson object at 0x107ad9ae0>]}
[0m12:22:22.373233 [debug] [MainThread]: Flushing usage events
[0m12:22:22.735227 [debug] [MainThread]: An error was encountered while trying to flush usage events
[0m13:22:15.986032 [debug] [MainThread]: Sending event: {'category': 'dbt', 'action': 'invocation', 'label': 'start', 'context': [<snowplow_tracker.self_describing_json.SelfDescribingJson object at 0x1048b3b60>, <snowplow_tracker.self_describing_json.SelfDescribingJson object at 0x107c3f9d0>, <snowplow_tracker.self_describing_json.SelfDescribingJson object at 0x107c3fb10>]}


============================== 13:22:15.991258 | bd0d3d9e-cfa9-4bde-9e49-bbd28125337a ==============================
[0m13:22:15.991258 [info ] [MainThread]: Running with dbt=1.10.9
[0m13:22:15.991950 [debug] [MainThread]: running dbt with arguments {'partial_parse': 'True', 'version_check': 'True', 'cache_selected_only': 'False', 'introspect': 'True', 'use_colors': 'True', 'send_anonymous_usage_stats': 'True', 'use_experimental_parser': 'False', 'warn_error': 'None', 'no_print': 'None', 'fail_fast': 'False', 'profiles_dir': '/Users/diaw/.dbt', 'static_parser': 'True', 'log_cache_events': 'False', 'target_path': 'None', 'log_path': 'logs', 'warn_error_options': 'WarnErrorOptionsV2(error=[], warn=[], silence=[])', 'empty': 'False', 'indirect_selection': 'eager', 'debug': 'False', 'printer_width': '80', 'invocation_command': 'dbt run', 'write_json': 'True', 'quiet': 'False', 'log_format': 'default'}
[0m13:22:15.992339 [error] [MainThread]: Encountered an error:
Runtime Error
  No dbt_project.yml found at expected path /Users/diaw/Downloads/dbt_notlimitail/dbt_project.yml
  Verify that each entry within packages.yml (and their transitive dependencies) contains a file named dbt_project.yml
  
[0m13:22:15.994104 [debug] [MainThread]: Resource report: {"command_name": "run", "command_success": false, "command_wall_clock_time": 0.07967429, "process_in_blocks": "0", "process_kernel_time": 0.129363, "process_mem_max_rss": "96206848", "process_out_blocks": "0", "process_user_time": 0.663715}
[0m13:22:15.994628 [debug] [MainThread]: Command `dbt run` failed at 13:22:15.994559 after 0.08 seconds
[0m13:22:15.994940 [debug] [MainThread]: Sending event: {'category': 'dbt', 'action': 'invocation', 'label': 'end', 'context': [<snowplow_tracker.self_describing_json.SelfDescribingJson object at 0x107b37360>, <snowplow_tracker.self_describing_json.SelfDescribingJson object at 0x107b3eb10>, <snowplow_tracker.self_describing_json.SelfDescribingJson object at 0x1078d99d0>]}
[0m13:22:15.995171 [debug] [MainThread]: Flushing usage events
[0m13:22:16.347163 [debug] [MainThread]: An error was encountered while trying to flush usage events
[0m13:23:53.260832 [debug] [MainThread]: Sending event: {'category': 'dbt', 'action': 'invocation', 'label': 'start', 'context': [<snowplow_tracker.self_describing_json.SelfDescribingJson object at 0x103cc3b60>, <snowplow_tracker.self_describing_json.SelfDescribingJson object at 0x1051d39d0>, <snowplow_tracker.self_describing_json.SelfDescribingJson object at 0x1051d3b10>]}


============================== 13:23:53.263863 | 48bafd2a-d27a-4b38-8481-5556c113bfff ==============================
[0m13:23:53.263863 [info ] [MainThread]: Running with dbt=1.10.9
[0m13:23:53.264160 [debug] [MainThread]: running dbt with arguments {'debug': 'False', 'profiles_dir': '/Users/diaw/.dbt', 'version_check': 'True', 'introspect': 'True', 'log_cache_events': 'False', 'indirect_selection': 'eager', 'static_parser': 'True', 'log_format': 'default', 'partial_parse': 'True', 'log_path': 'logs', 'empty': 'None', 'warn_error': 'None', 'use_colors': 'True', 'write_json': 'True', 'no_print': 'None', 'fail_fast': 'False', 'invocation_command': 'dbt deps', 'send_anonymous_usage_stats': 'True', 'use_experimental_parser': 'False', 'quiet': 'False', 'target_path': 'None', 'cache_selected_only': 'False', 'warn_error_options': 'WarnErrorOptionsV2(error=[], warn=[], silence=[])', 'printer_width': '80'}
[0m13:23:53.264584 [error] [MainThread]: Encountered an error:
Runtime Error
  No dbt_project.yml found at expected path /Users/diaw/Downloads/dbt_notlimitail/dbt_project.yml
  Verify that each entry within packages.yml (and their transitive dependencies) contains a file named dbt_project.yml
  
[0m13:23:53.266367 [debug] [MainThread]: Resource report: {"command_name": "deps", "command_success": false, "command_wall_clock_time": 0.044878166, "process_in_blocks": "0", "process_kernel_time": 0.103256, "process_mem_max_rss": "106659840", "process_out_blocks": "0", "process_user_time": 0.620492}
[0m13:23:53.266624 [debug] [MainThread]: Command `dbt deps` failed at 13:23:53.266578 after 0.05 seconds
[0m13:23:53.266779 [debug] [MainThread]: Sending event: {'category': 'dbt', 'action': 'invocation', 'label': 'end', 'context': [<snowplow_tracker.self_describing_json.SelfDescribingJson object at 0x1050d7360>, <snowplow_tracker.self_describing_json.SelfDescribingJson object at 0x1050deb10>, <snowplow_tracker.self_describing_json.SelfDescribingJson object at 0x105079ae0>]}
[0m13:23:53.266927 [debug] [MainThread]: Flushing usage events
[0m13:23:53.618533 [debug] [MainThread]: An error was encountered while trying to flush usage events
[0m13:59:13.908755 [debug] [MainThread]: Sending event: {'category': 'dbt', 'action': 'invocation', 'label': 'start', 'context': [<snowplow_tracker.self_describing_json.SelfDescribingJson object at 0x107fc7b60>, <snowplow_tracker.self_describing_json.SelfDescribingJson object at 0x10a33f9d0>, <snowplow_tracker.self_describing_json.SelfDescribingJson object at 0x10a33fb10>]}


============================== 13:59:13.911595 | 9f359905-8159-4090-b15c-b207f7afea43 ==============================
[0m13:59:13.911595 [info ] [MainThread]: Running with dbt=1.10.9
[0m13:59:13.911885 [debug] [MainThread]: running dbt with arguments {'partial_parse': 'True', 'send_anonymous_usage_stats': 'True', 'log_cache_events': 'False', 'warn_error': 'None', 'write_json': 'True', 'profiles_dir': '/Users/diaw/.dbt', 'target_path': 'None', 'empty': 'False', 'indirect_selection': 'eager', 'use_experimental_parser': 'False', 'cache_selected_only': 'False', 'log_path': 'logs', 'quiet': 'False', 'use_colors': 'True', 'printer_width': '80', 'static_parser': 'True', 'debug': 'False', 'warn_error_options': 'WarnErrorOptionsV2(error=[], warn=[], silence=[])', 'fail_fast': 'False', 'log_format': 'default', 'introspect': 'True', 'version_check': 'True', 'no_print': 'None', 'invocation_command': 'dbt run'}
[0m13:59:13.912182 [error] [MainThread]: Encountered an error:
Runtime Error
  No dbt_project.yml found at expected path /Users/diaw/Downloads/dbt_notlimitail/dbt_project.yml
  Verify that each entry within packages.yml (and their transitive dependencies) contains a file named dbt_project.yml
  
[0m13:59:13.913949 [debug] [MainThread]: Resource report: {"command_name": "run", "command_success": false, "command_wall_clock_time": 0.041268874, "process_in_blocks": "0", "process_kernel_time": 0.119438, "process_mem_max_rss": "107069440", "process_out_blocks": "0", "process_user_time": 0.613761}
[0m13:59:13.914241 [debug] [MainThread]: Command `dbt run` failed at 13:59:13.914186 after 0.04 seconds
[0m13:59:13.914417 [debug] [MainThread]: Sending event: {'category': 'dbt', 'action': 'invocation', 'label': 'end', 'context': [<snowplow_tracker.self_describing_json.SelfDescribingJson object at 0x10a237360>, <snowplow_tracker.self_describing_json.SelfDescribingJson object at 0x10a23eb10>, <snowplow_tracker.self_describing_json.SelfDescribingJson object at 0x10a0d99d0>]}
[0m13:59:13.914604 [debug] [MainThread]: Flushing usage events
[0m13:59:14.269332 [debug] [MainThread]: An error was encountered while trying to flush usage events
[0m14:04:33.916767 [debug] [MainThread]: Sending event: {'category': 'dbt', 'action': 'invocation', 'label': 'start', 'context': [<snowplow_tracker.self_describing_json.SelfDescribingJson object at 0x1076f7b60>, <snowplow_tracker.self_describing_json.SelfDescribingJson object at 0x108c0f9d0>, <snowplow_tracker.self_describing_json.SelfDescribingJson object at 0x108c0fb10>]}


============================== 14:04:33.919617 | e7a26aeb-34f4-4622-89f3-c949887648c7 ==============================
[0m14:04:33.919617 [info ] [MainThread]: Running with dbt=1.10.9
[0m14:04:33.919910 [debug] [MainThread]: running dbt with arguments {'log_path': 'logs', 'debug': 'False', 'log_format': 'default', 'introspect': 'True', 'use_colors': 'True', 'quiet': 'False', 'target_path': 'None', 'profiles_dir': '/Users/diaw/.dbt', 'send_anonymous_usage_stats': 'True', 'static_parser': 'True', 'log_cache_events': 'False', 'partial_parse': 'True', 'no_print': 'None', 'empty': 'False', 'use_experimental_parser': 'False', 'printer_width': '80', 'warn_error': 'None', 'cache_selected_only': 'False', 'warn_error_options': 'WarnErrorOptionsV2(error=[], warn=[], silence=[])', 'fail_fast': 'False', 'write_json': 'True', 'indirect_selection': 'eager', 'version_check': 'True', 'invocation_command': 'dbt run'}
[0m14:04:33.920190 [error] [MainThread]: Encountered an error:
Runtime Error
  No dbt_project.yml found at expected path /Users/diaw/Downloads/dbt_notlimitail/dbt_project.yml
  Verify that each entry within packages.yml (and their transitive dependencies) contains a file named dbt_project.yml
  
[0m14:04:33.921920 [debug] [MainThread]: Resource report: {"command_name": "run", "command_success": false, "command_wall_clock_time": 0.042170208, "process_in_blocks": "0", "process_kernel_time": 0.105174, "process_mem_max_rss": "106627072", "process_out_blocks": "0", "process_user_time": 0.612062}
[0m14:04:33.922203 [debug] [MainThread]: Command `dbt run` failed at 14:04:33.922155 after 0.04 seconds
[0m14:04:33.922370 [debug] [MainThread]: Sending event: {'category': 'dbt', 'action': 'invocation', 'label': 'end', 'context': [<snowplow_tracker.self_describing_json.SelfDescribingJson object at 0x108b07360>, <snowplow_tracker.self_describing_json.SelfDescribingJson object at 0x108b0eb10>, <snowplow_tracker.self_describing_json.SelfDescribingJson object at 0x108aa99d0>]}
[0m14:04:33.922681 [debug] [MainThread]: Flushing usage events
[0m14:04:34.285336 [debug] [MainThread]: An error was encountered while trying to flush usage events
